Workbook

Sheet Hoja1
A1: CODI | B1: #id user | C1: Swipe Date | D1: Amount | E1: MONEDA | F1: User | G1: Descriptor | H1: Merchant Name | I1: Expense Type | J1: DESCRIPCION DEL CARGO | K1: FOLIO DE FACTURA | L1: Cuenta contable | M1: Cargo | N1: Descripcion
A2: {=_xlfn._xlws.FILTER(_xlfn.VSTACK('#16 Rogelio:#88 Rene Granados'!A12:K206),_xlfn.VSTACK('#16 Rogelio:#88 Rene Granados'!A12:A206)<>0)} -> TRX1294 | B2: #16 | C2: 46055.417 | D2: 363.15 | E2: USD | F2: Rogelio Gamez | G2: OPENAI *CHATGPT SUBSCR SAN FRANCISCO USA | H2: Openai | I2: Tech&Product | J2: 0 | K2: 0 | L2: =VLOOKUP(B2,[1]Total!$B:$Q,16,0) -> 603.81.004 Gastos de Oficina | M2: =D2 -> 363.15 | N2: =CONCATENATE(F2," ",G2," ",H2," ",I2," ",J2," ",K2," ") -> Rogelio Gamez OPENAI *CHATGPT SUBSCR SAN FRANCISCO USA Openai Tech&Product 0 0
A3: TRX1233 | B3: #16 | C3: 46058.417 | D3: 6615.11 | E3: MXN | F3: Rogelio Gamez | G3: PAYU *GOOGLE ADS MIGUEL HIDALG MEX | H3: Google | I3: Sales | J3: Marketing | K3: 0 | L3: 603.38.002 | M3: =D3 -> 6615.11 | N3: =CONCATENATE(F3," ",G3," ",H3," ",I3," ",J3," ",K3," ") -> Rogelio Gamez PAYU *GOOGLE ADS MIGUEL HIDALG MEX Google Sales Marketing 0
A4: TRX1185 | B4: #16 | C4: 46059.417 | D4: 696.88 | E4: MXN | F4: Rogelio Gamez | G4: Amazon Mexico CMX MEX | H4: Amazon | I4: Office expenses | J4: 0 | K4: 0 | L4: =VLOOKUP(B4,[1]Total!$B:$Q,16,0) -> 603.81.004 Gastos de Oficina | M4: =D4 -> 696.88 | N4: =CONCATENATE(F4," ",G4," ",H4," ",I4," ",J4," ",K4," ") -> Rogelio Gamez Amazon Mexico CMX MEX Amazon Office expenses 0 0
A5: TRX1184 | B5: #16 | C5: 46059.417 | D5: 903.99 | E5: MXN | F5: Rogelio Gamez | G5: Amazon Mexico CMX MEX | H5: Amazon | I5: Office expenses | J5: 0 | K5: 0 | L5: =VLOOKUP(B5,[1]Total!$B:$Q,16,0) -> 603.81.004 Gastos de Oficina | M5: =D5 -> 903.99 | N5: =CONCATENATE(F5," ",G5," ",H5," ",I5," ",J5," ",K5," ") -> Rogelio Gamez Amazon Mexico CMX MEX Amazon Office expenses 0 0
A6: TRX1179 | B6: #16 | C6: 46059.417 | D6: 647.17 | E6: MXN | F6: Rogelio Gamez | G6: Amazon Mexico CMX MEX | H6: Amazon | I6: Tech&Product | J6: 0 | K6: 0 | L6: =VLOOKUP(B6,[1]Total!$B:$Q,16,0) -> 603.81.004 Gastos de Oficina | M6: =D6 -> 647.17 | N6: =CONCATENATE(F6," ",G6," ",H6," ",I6," ",J6," ",K6," ") -> Rogelio Gamez Amazon Mexico CMX MEX Amazon Tech&Product 0 0
A7: TRX1177 | B7: #16 | C7: 46059.417 | D7: 620.01 | E7: MXN | F7: Rogelio Gamez | G7: Amazon Mexico CMX MEX | H7: Amazon | I7: Office expenses | J7: 0 | K7: 0 | L7: =VLOOKUP(B7,[1]Total!$B:$Q,16,0) -> 603.81.004 Gastos de Oficina | M7: =D7 -> 620.01 | N7: =CONCATENATE(F7," ",G7," ",H7," ",I7," ",J7," ",K7," ") -> Rogelio Gamez Amazon Mexico CMX MEX Amazon Office expenses 0 0
A8: TRX1170 | B8: #16 | C8: 46059.417 | D8: 4420 | E8: MXN | F8: Rogelio Gamez | G8: MERCADOPAGO *FIERCEMX Ciudad de Mex MEX | H8: Mercadopago | I8: Office expenses | J8: 0 | K8: 0 | L8: =VLOOKUP(B8,[1]Total!$B:$Q,16,0) -> 603.81.004 Gastos de Oficina | M8: =D8 -> 4420 | N8: =CONCATENATE(F8," ",G8," ",H8," ",I8," ",J8," ",K8," ") -> Rogelio Gamez MERCADOPAGO *FIERCEMX Ciudad de Mex MEX Mercadopago Office expenses 0 0
A9: TRX1157 | B9: #16 | C9: 46059.417 | D9: 8990 | E9: MXN | F9: Rogelio Gamez | G9: STR*SYNTAGE CIUDAD DE MEX MEX | H9: Str Syntage Ciudad De Mex Mex | I9: Office expenses | J9: 0 | K9: 0 | L9: =VLOOKUP(B9,[1]Total!$B:$Q,16,0) -> 603.81.004 Gastos de Oficina | M9: =D9 -> 8990 | N9: =CONCATENATE(F9," ",G9," ",H9," ",I9," ",J9," ",K9," ") -> Rogelio Gamez STR*SYNTAGE CIUDAD DE MEX MEX Str Syntage Ciudad De Mex Mex Office expenses 0 0
A10: TRX1541 | B10: #16 | C10: 46061.417 | D10: 17401.35 | E10: USD | F10: Rogelio Gamez | G10: NOTION LABS, INC. SAN FRANCISCO USA | H10: Notion | I10: Office expenses | J10: 0 | K10: 0 | L10: =VLOOKUP(B10,[1]Total!$B:$Q,16,0) -> 603.81.004 Gastos de Oficina | M10: =D10 -> 17401.35 | N10: =CONCATENATE(F10," ",G10," ",H10," ",I10," ",J10," ",K10," ") -> Rogelio Gamez NOTION LABS, INC. SAN FRANCISCO USA Notion Office expenses 0 0
A11: TRX1648 | B11: #16 | C11: 46061.417 | D11: 151306.79 | E11: USD | F11: Rogelio Gamez | G11: Amazon web services SEATTLE USA | H11: Amazon Web Services | I11: Sales | J11: Marketing | K11: 0 | L11: 603.38.002 | M11: =D11 -> 151306.79 | N11: =CONCATENATE(F11," ",G11," ",H11," ",I11," ",J11," ",K11," ") -> Rogelio Gamez Amazon web services SEATTLE USA Amazon Web Services Sales Marketing 0
A12: TRX1277 | B12: #16 | C12: 46062.417 | D12: 39 | E12: MXN | F12: Rogelio Gamez | G12: OFFICE DEPOT STAM TLANEPANTLA E MEX | H12: Office Depot | I12: Office expenses | J12: 0 | K12: 0 | L12: =VLOOKUP(B12,[1]Total!$B:$Q,16,0) -> 603.81.004 Gastos de Oficina | M12: =D12 -> 39 | N12: =CONCATENATE(F12," ",G12," ",H12," ",I12," ",J12," ",K12," ") -> Rogelio Gamez OFFICE DEPOT STAM TLANEPANTLA E MEX Office Depot Office expenses 0 0
A13: TRX1426 | B13: #16 | C13: 46064.417 | D13: 259.94 | E13: MXN | F13: Rogelio Gamez | G13: UBER * PENDING CMX MEX | H13: Uber | I13: G&A expenses | J13: 0 | K13: 0 | L13: =VLOOKUP(B13,[1]Total!$B:$Q,16,0) -> 603.81.004 Gastos de Oficina | M13: =D13 -> 259.94 | N13: =CONCATENATE(F13," ",G13," ",H13," ",I13," ",J13," ",K13," ") -> Rogelio Gamez UBER * PENDING CMX MEX Uber G&A expenses 0 0
A14: TRX1453 | B14: #16 | C14: 46065.417 | D14: 179 | E14: MXN | F14: Rogelio Gamez | G14: Amazon Mexico CMX MEX | H14: Amazon | I14: Office expenses | J14: 0 | K14: 0 | L14: =VLOOKUP(B14,[1]Total!$B:$Q,16,0) -> 603.81.004 Gastos de Oficina | M14: =D14 -> 179 | N14: =CONCATENATE(F14," ",G14," ",H14," ",I14," ",J14," ",K14," ") -> Rogelio Gamez Amazon Mexico CMX MEX Amazon Office expenses 0 0
A15: TRX1331 | B15: #16 | C15: 46065.417 | D15: 939.94 | E15: MXN | F15: Rogelio Gamez | G15: Amazon Mexico CMX MEX | H15: Amazon | I15: G&A expenses | J15: 0 | K15: 0 | L15: =VLOOKUP(B15,[1]Total!$B:$Q,16,0) -> 603.81.004 Gastos de Oficina | M15: =D15 -> 939.94 | N15: =CONCATENATE(F15," ",G15," ",H15," ",I15," ",J15," ",K15," ") -> Rogelio Gamez Amazon Mexico CMX MEX Amazon G&A expenses 0 0
A16: TRX1926 | B16: #16 | C16: 46065.417 | D16: 499.72 | E16: MXN | F16: Rogelio Gamez | G16: Amazon Mexico CMX MEX | H16: Amazon | I16: Tech&Product | J16: 0 | K16: 0 | L16: =VLOOKUP(B16,[1]Total!$B:$Q,16,0) -> 603.81.004 Gastos de Oficina | M16: =D16 -> 499.72 | N16: =CONCATENATE(F16," ",G16," ",H16," ",I16," ",J16," ",K16," ") -> Rogelio Gamez Amazon Mexico CMX MEX Amazon Tech&Product 0 0
A17: TRX1345 | B17: #16 | C17: 46065.417 | D17: 299.99 | E17: MXN | F17: Rogelio Gamez | G17: Amazon Mexico CMX MEX | H17: Amazon | I17: Office expenses | J17: 0 | K17: 0 | L17: =VLOOKUP(B17,[1]Total!$B:$Q,16,0) -> 603.81.004 Gastos de Oficina | M17: =D17 -> 299.99 | N17: =CONCATENATE(F17," ",G17," ",H17," ",I17," ",J17," ",K17," ") -> Rogelio Gamez Amazon Mexico CMX MEX Amazon Office expenses 0 0
A18: TRX1338 | B18: #16 | C18: 46065.417 | D18: 10000 | E18: MXN | F18: Rogelio Gamez | G18: PAYU *GOOGLE ADS MIGUEL HIDALG MEX | H18: Google | I18: Tech&Product | J18: 0 | K18: 0 | L18: =VLOOKUP(B18,[1]Total!$B:$Q,16,0) -> 603.81.004 Gastos de Oficina | M18: =D18 -> 10000 | N18: =CONCATENATE(F18," ",G18," ",H18," ",I18," ",J18," ",K18," ") -> Rogelio Gamez PAYU *GOOGLE ADS MIGUEL HIDALG MEX Google Tech&Product 0 0
A19: TRX1265 | B19: #16 | C19: 46065.417 | D19: 0.86 | E19: MXN | F19: Rogelio Gamez | G19: 20260211T04:49:55/Amazon Mexico\AV BLVD MANUEL A CAMACHO\CMX\11510 MEXMEX | H19: Amazon | I19: Sales | J19: Marketing | K19: 0 | L19: =VLOOKUP(B19,[1]Total!$B:$Q,16,0) -> 603.81.004 Gastos de Oficina | M19: =D19 -> 0.86 | N19: =CONCATENATE(F19," ",G19," ",H19," ",I19," ",J19," ",K19," ") -> Rogelio Gamez 20260211T04:49:55/Amazon Mexico\AV BLVD MANUEL A CAMACHO\CMX\11510 MEXMEX Amazon Sales Marketing 0
A20: TRX1303 | B20: #16 | C20: 46072.417 | D20: 300 | E20: MXN | F20: Rogelio Gamez | G20: ABTS 12911 PRADO NORTE CIUDAD DE MEX MEX | H20: Abts Prado Norte Ciudad De Mex Mex | I20: Tech&Product | J20: 0 | K20: 0 | L20: =VLOOKUP(B20,[1]Total!$B:$Q,16,0) -> 603.81.004 Gastos de Oficina | M20: =D20 -> 300 | N20: =CONCATENATE(F20," ",G20," ",H20," ",I20," ",J20," ",K20," ") -> Rogelio Gamez ABTS 12911 PRADO NORTE CIUDAD DE MEX MEX Abts Prado Norte Ciudad De Mex Mex Tech&Product 0 0
A21: TRX1313 | B21: #16 | C21: 46074.417 | D21: 10000 | E21: MXN | F21: Rogelio Gamez | G21: PAYU *GOOGLE ADS MIGUEL HIDALG MEX | H21: Google | I21: Office expenses | J21: 0 | K21: 0 | L21: =VLOOKUP(B21,[1]Total!$B:$Q,16,0) -> 603.81.004 Gastos de Oficina | M21: =D21 -> 10000 | N21: =CONCATENATE(F21," ",G21," ",H21," ",I21," ",J21," ",K21," ") -> Rogelio Gamez PAYU *GOOGLE ADS MIGUEL HIDALG MEX Google Office expenses 0 0
A22: TRX1077 | B22: #16 | C22: 46075.417 | D22: 377.09 | E22: USD | F22: Rogelio Gamez | G22: Box_UK London GBR | H22: Box_Uk London | I22: Tech&Product | J22: 0 | K22: 0 | L22: =VLOOKUP(B22,[1]Total!$B:$Q,16,0) -> 603.81.004 Gastos de Oficina | M22: =D22 -> 377.09 | N22: =CONCATENATE(F22," ",G22," ",H22," ",I22," ",J22," ",K22," ") -> Rogelio Gamez Box_UK London GBR Box_Uk London Tech&Product 0 0
A23: TRX1097 | B23: #16 | C23: 46076.417 | D23: 320.53 | E23: EUR | F23: Rogelio Gamez | G23: WEGLOT PARIS FRA | H23: Weglot Paris Fra | I23: Tech&Product | J23: 0 | K23: 0 | L23: =VLOOKUP(B23,[1]Total!$B:$Q,16,0) -> 603.81.004 Gastos de Oficina | M23: =D23 -> 320.53 | N23: =CONCATENATE(F23," ",G23," ",H23," ",I23," ",J23," ",K23," ") -> Rogelio Gamez WEGLOT PARIS FRA Weglot Paris Fra Tech&Product 0 0
A24: TRX1285 | B24: #66 | C24: 46056.417 | D24: 262 | E24: MXN | F24: Erik Castillo | G24: HAMBURGUESAS DIANA TIZAYUCA HGO MEX | H24: Hamburguesas Diana Tizayuca Hgo Mex | I24: Transaction cost | J24: Gasolina | K24: A18529 | L24: =VLOOKUP(B24,[1]Total!$B:$Q,16,0) -> 602.34.002 Gastos por visita tencica | M24: =D24 -> 262 | N24: =CONCATENATE(F24," ",G24," ",H24," ",I24," ",J24," ",K24," ") -> Erik Castillo HAMBURGUESAS DIANA TIZAYUCA HGO MEX Hamburguesas Diana Tizayuca Hgo Mex Transaction cost Gasolina A18529
A25: TRX1275 | B25: #66 | C25: 46057.417 | D25: 1214.65 | E25: MXN | F25: Erik Castillo | G25: ENERGETICOS ZAPATA 4 TIZAYUCA HGO MEX | H25: Energeticos Zapata 4 Tizayuca Hgo Mex | I25: Transaction cost | J25: Recarga de TAG | K25: AAAU-581966 | L25: =VLOOKUP(B25,[1]Total!$B:$Q,16,0) -> 602.34.002 Gastos por visita tencica | M25: =D25 -> 1214.65 | N25: =CONCATENATE(F25," ",G25," ",H25," ",I25," ",J25," ",K25," ") -> Erik Castillo ENERGETICOS ZAPATA 4 TIZAYUCA HGO MEX Energeticos Zapata 4 Tizayuca Hgo Mex Transaction cost Recarga de TAG AAAU-581966
A26: TRX1903 | B26: #66 | C26: 46059.417 | D26: 107.5 | E26: MXN | F26: Erik Castillo | G26: OXXOSAN ANTONIO 17 MEX CUAUTITLAN EM MEX | H26: Oxxosan Antonio 17 Mex Cuautitlan Em Mex | I26: Transaction cost | J26: Consumo con Personal Creaceric | K26: DOMBNTAAQH 15621 | L26: =VLOOKUP(B26,[1]Total!$B:$Q,16,0) -> 602.34.002 Gastos por visita tencica | M26: =D26 -> 107.5 | N26: =CONCATENATE(F26," ",G26," ",H26," ",I26," ",J26," ",K26," ") -> Erik Castillo OXXOSAN ANTONIO 17 MEX CUAUTITLAN EM MEX Oxxosan Antonio 17 Mex Cuautitlan Em Mex Transaction cost Consumo con Personal Creaceric DOMBNTAAQH 15621
A27: TRX1082 | B27: #66 | C27: 46060.417 | D27: 295 | E27: MXN | F27: Erik Castillo | G27: MERCADOPAGO *SELENEGH Tizayuca MEX | H27: Mercadopago | I27: Transaction cost | J27: Gasolina entrega de auto rentado | K27: A18601 | L27: =VLOOKUP(B27,[1]Total!$B:$Q,16,0) -> 602.34.002 Gastos por visita tencica | M27: =D27 -> 295 | N27: =CONCATENATE(F27," ",G27," ",H27," ",I27," ",J27," ",K27," ") -> Erik Castillo MERCADOPAGO *SELENEGH Tizayuca MEX Mercadopago Transaction cost Gasolina entrega de auto rentado A18601
A28: TRX1108 | B28: #66 | C28: 46060.417 | D28: 100 | E28: MXN | F28: Erik Castillo | G28: OXXO EJERCITO TIZAYUCA HGO MEX | H28: Oxxo | I28: Transaction cost | J28: Traslado | K28: No me facturo | L28: =VLOOKUP(B28,[1]Total!$B:$Q,16,0) -> 602.34.002 Gastos por visita tencica | M28: =D28 -> 100 | N28: =CONCATENATE(F28," ",G28," ",H28," ",I28," ",J28," ",K28," ") -> Erik Castillo OXXO EJERCITO TIZAYUCA HGO MEX Oxxo Transaction cost Traslado No me facturo
A29: TRX1603 | B29: #66 | C29: 46060.417 | D29: 375.5 | E29: MXN | F29: Erik Castillo | G29: BGA AURRERA TIZAYUCA TIZAYUCA HGO MEX | H29: Bga Aurrera Tizayuca Tizayuca Hgo Mex | I29: Transaction cost | J29: Recarga de auto sin renta | K29: AAAU-581966 | L29: =VLOOKUP(B29,[1]Total!$B:$Q,16,0) -> 602.34.002 Gastos por visita tencica | M29: =D29 -> 375.5 | N29: =CONCATENATE(F29," ",G29," ",H29," ",I29," ",J29," ",K29," ") -> Erik Castillo BGA AURRERA TIZAYUCA TIZAYUCA HGO MEX Bga Aurrera Tizayuca Tizayuca Hgo Mex Transaction cost Recarga de auto sin renta AAAU-581966
A30: TRX1660 | B30: #66 | C30: 46063.417 | D30: 1386.72 | E30: MXN | F30: Erik Castillo | G30: ENERGETICOS ZAPATA 1 TIZAYUCA HGO MEX | H30: Energeticos Zapata 1 Tizayuca Hgo Mex | I30: Transaction cost | J30: Consumo | K30: ya no alcance a facturar | L30: =VLOOKUP(B30,[1]Total!$B:$Q,16,0) -> 602.34.002 Gastos por visita tencica | M30: =D30 -> 1386.72 | N30: =CONCATENATE(F30," ",G30," ",H30," ",I30," ",J30," ",K30," ") -> Erik Castillo ENERGETICOS ZAPATA 1 TIZAYUCA HGO MEX Energeticos Zapata 1 Tizayuca Hgo Mex Transaction cost Consumo ya no alcance a facturar
A31: TRX1877 | B31: #66 | C31: 46063.417 | D31: 469 | E31: MXN | F31: Erik Castillo | G31: CASHI ECOMMERCE RC CIUDAD DE MEX MEX | H31: Cashi Ecommerce Rc Ciudad De Mex Mex | I31: Transaction cost | J31: Consumo | K31: IBABK342054 | L31: =VLOOKUP(B31,[1]Total!$B:$Q,16,0) -> 602.34.002 Gastos por visita tencica | M31: =D31 -> 469 | N31: =CONCATENATE(F31," ",G31," ",H31," ",I31," ",J31," ",K31," ") -> Erik Castillo CASHI ECOMMERCE RC CIUDAD DE MEX MEX Cashi Ecommerce Rc Ciudad De Mex Mex Transaction cost Consumo IBABK342054
A32: TRX1125 | B32: #66 | C32: 46063.417 | D32: 96.5 | E32: MXN | F32: Erik Castillo | G32: OXXO G ZAPATA PAC TIZAYUCA HGO MEX | H32: Oxxo | I32: Transaction cost | J32: Viaje a Veracruz ida y vuelta | K32: 151715038 | L32: =VLOOKUP(B32,[1]Total!$B:$Q,16,0) -> 602.34.002 Gastos por visita tencica | M32: =D32 -> 96.5 | N32: =CONCATENATE(F32," ",G32," ",H32," ",I32," ",J32," ",K32," ") -> Erik Castillo OXXO G ZAPATA PAC TIZAYUCA HGO MEX Oxxo Transaction cost Viaje a Veracruz ida y vuelta 151715038
A33: TRX1420 | B33: #66 | C33: 46064.417 | D33: 33 | E33: MXN | F33: Erik Castillo | G33: OXXO G ZAPATA PAC TIZAYUCA HGO MEX | H33: Oxxo | I33: Transaction cost | J33: Hotel Veracruz | K33: FA9310 | L33: =VLOOKUP(B33,[1]Total!$B:$Q,16,0) -> 602.34.002 Gastos por visita tencica | M33: =D33 -> 33 | N33: =CONCATENATE(F33," ",G33," ",H33," ",I33," ",J33," ",K33," ") -> Erik Castillo OXXO G ZAPATA PAC TIZAYUCA HGO MEX Oxxo Transaction cost Hotel Veracruz FA9310
A34: TRX1580 | B34: #66 | C34: 46064.417 | D34: 1014 | E34: MXN | F34: Erik Castillo | G34: OXXO G ZAPATA PAC TIZAYUCA HGO MEX | H34: Oxxo | I34: Transaction cost | J34: Electrico Vehiculo | K34: Folia A 24860 | L34: =VLOOKUP(B34,[1]Total!$B:$Q,16,0) -> 602.34.002 Gastos por visita tencica | M34: =D34 -> 1014 | N34: =CONCATENATE(F34," ",G34," ",H34," ",I34," ",J34," ",K34," ") -> Erik Castillo OXXO G ZAPATA PAC TIZAYUCA HGO MEX Oxxo Transaction cost Electrico Vehiculo Folia A 24860
A35: TRX1701 | B35: #66 | C35: 46065.417 | D35: 350 | E35: MXN | F35: Erik Castillo | G35: HAMBURGUESAS DIANA TIZAYUCA HGO MEX | H35: Hamburguesas Diana Tizayuca Hgo Mex | I35: Transaction cost | J35: Seguridad | K35: 544913E5-5BEB-49F1-A1A4-C7A64C00862C | L35: =VLOOKUP(B35,[1]Total!$B:$Q,16,0) -> 602.34.002 Gastos por visita tencica | M35: =D35 -> 350 | N35: =CONCATENATE(F35," ",G35," ",H35," ",I35," ",J35," ",K35," ") -> Erik Castillo HAMBURGUESAS DIANA TIZAYUCA HGO MEX Hamburguesas Diana Tizayuca Hgo Mex Transaction cost Seguridad 544913E5-5BEB-49F1-A1A4-C7A64C00862C
A36: TRX1647 | B36: #66 | C36: 46066.417 | D36: 139.7 | E36: MXN | F36: Erik Castillo | G36: WWO 2269 MP TIZAYUCA HGO MEX | H36: Wwo 2269 Mp Tizayuca Hgo Mex | I36: Transaction cost | J36: Gasolina | K36: A18797 | L36: =VLOOKUP(B36,[1]Total!$B:$Q,16,0) -> 602.34.002 Gastos por visita tencica | M36: =D36 -> 139.7 | N36: =CONCATENATE(F36," ",G36," ",H36," ",I36," ",J36," ",K36," ") -> Erik Castillo WWO 2269 MP TIZAYUCA HGO MEX Wwo 2269 Mp Tizayuca Hgo Mex Transaction cost Gasolina A18797
A37: TRX1498 | B37: #66 | C37: 46066.417 | D37: 407.98 | E37: MXN | F37: Erik Castillo | G37: FAR GUAD 2318 TIZAYUCA HGO MEX | H37: Far Guad 2318 Tizayuca Hgo Mex | I37: Transaction cost | J37: Recarga | K37: 7513083260122161507881 | L37: =VLOOKUP(B37,[1]Total!$B:$Q,16,0) -> 602.34.002 Gastos por visita tencica | M37: =D37 -> 407.98 | N37: =CONCATENATE(F37," ",G37," ",H37," ",I37," ",J37," ",K37," ") -> Erik Castillo FAR GUAD 2318 TIZAYUCA HGO MEX Far Guad 2318 Tizayuca Hgo Mex Transaction cost Recarga 7513083260122161507881
A38: TRX1294 | B38: #66 | C38: 46067.417 | D38: 1480.2 | E38: MXN | F38: Erik Castillo | G38: ENERGETICOS ZAPATA 3 TIZAYUCA HGO MEX | H38: Energeticos Zapata 3 Tizayuca Hgo Mex | I38: Transaction cost | J38: Consumo | K38: 7545056260122161139465 | L38: =VLOOKUP(B38,[1]Total!$B:$Q,16,0) -> 602.34.002 Gastos por visita tencica | M38: =D38 -> 1480.2 | N38: =CONCATENATE(F38," ",G38," ",H38," ",I38," ",J38," ",K38," ") -> Erik Castillo ENERGETICOS ZAPATA 3 TIZAYUCA HGO MEX Energeticos Zapata 3 Tizayuca Hgo Mex Transaction cost Consumo 7545056260122161139465
A39: TRX1835 | B39: #66 | C39: 46068.417 | D39: 149 | E39: MXN | F39: Erik Castillo | G39: OXXO G ZAPATA PAC TIZAYUCA HGO MEX | H39: Oxxo | I39: Transaction cost | J39: Consumo | K39: 182BFE68-095E-4026-B953-EA81B419CDD5 | L39: =VLOOKUP(B39,[1]Total!$B:$Q,16,0) -> 602.34.002 Gastos por visita tencica | M39: =D39 -> 149 | N39: =CONCATENATE(F39," ",G39," ",H39," ",I39," ",J39," ",K39," ") -> Erik Castillo OXXO G ZAPATA PAC TIZAYUCA HGO MEX Oxxo Transaction cost Consumo 182BFE68-095E-4026-B953-EA81B419CDD5
A40: TRX1753 | B40: #66 | C40: 46069.417 | D40: 245 | E40: MXN | F40: Erik Castillo | G40: OXXO FUENTES TIZAYUCA TIZAYUCA HGO MEX | H40: Oxxo | I40: Transaction cost | J40: Consumo para traslados | K40: ICAGL581003 | L40: =VLOOKUP(B40,[1]Total!$B:$Q,16,0) -> 602.34.002 Gastos por visita tencica | M40: =D40 -> 245 | N40: =CONCATENATE(F40," ",G40," ",H40," ",I40," ",J40," ",K40," ") -> Erik Castillo OXXO FUENTES TIZAYUCA TIZAYUCA HGO MEX Oxxo Transaction cost Consumo para traslados ICAGL581003
...

Sheet Consolidación de datos 
A1: CODI | B1: #id user | C1: Swipe Date | D1: Amount | E1: MONEDA | F1: User | G1: Descriptor | H1: Merchant Name | I1: Expense Type | J1: DESCRIPCION DEL CARGO | K1: FOLIO DE FACTURA
A2: =IFERROR(__xludf.DUMMYFUNCTION("{QUERY('#2 Cesar'!A12:K1000,""where A is not null"");QUERY('#3 Cesar Uriel'!A12:K1000,""where A is not null"");QUERY('#4 Daniel Autrique'!A12:K1000,""where A is not null"");QUERY('#5 Fernanda'!A12:K1000,""where A is not null"");QUERY('#6 Fernando Sanchez'"&"!A12:K1000,""where A is not null"");QUERY('#7 Isaac'!A12:K1000,""where A is not null"");QUERY('#8 Jose Ignacio'!A12:K1000,""where A is not null"");QUERY('#9 Jose Maria'!A12:K1000,""where A is not null"");QUERY('#11 Juan Carlos'!A12:K1000,""where A is not "&"null"");QUERY('#13 Miguel'!A12:K1000,""where A is not null"");QUERY('#14 Patricio. '!A12:K1000,""where A is not null"");QUERY('#16 Rogelio'!A12:K1000,""where A is not null"");QUERY('#17 Sebastian'!A12:K1000,""where A is not null"");QUERY('#19 Daniel Aleja"&"ndro Castillo R'!A12:K1000,""where A is not null"");QUERY('#20 Gerardo Guadalupe Ruiz Huer'!A12:K1000,""where A is not null"");QUERY('#21 Jesus Gonzalez Grana'!A12:K1000,""where A is not null"");QUERY('#24 Andres Camacho'!A12:K1000,""where A is not null"""&");QUERY('#25 Jorge Estrada'!A12:K1000,""where A is not null"");QUERY('#26 Alexandra Ballesteros'!A12:K1000,""where A is not null"");QUERY('#28 Fernando Villalobos'!A12:K1000,""where A is not null"");QUERY('#30 Manuel Ibarra'!A12:K1000,""where A is not nul"&"l"");QUERY(' #31 Emiliano Cavazos'!A12:K1000,""where A is not null"");QUERY('#34 Juan Pablo Ramos'!A12:K1000,""where A is not null"");QUERY('#35 Termis'!A12:K1000,""where A is not null"");QUERY('#37 Angel Pantoja'!A12:K1000,""where A is not null"");QUERY("&"'#40 Gabriela Zacarias'!A12:K1000,""where A is not null"");QUERY('#41 Jose Arechavala'!A12:K1000,""where A is not null"");QUERY('#42 Rodrigo Perea'!A12:K1000,""where A is not null"");QUERY('#43 Pablo Ortiz'!A12:K1000,""where A is not null"");QUERY('#44 JP"&" Hammerstein'!A12:K1000,""where A is not null"");QUERY('#45 Erick Cival'!A12:K1000,""where A is not null"");QUERY('#46 Kallie Parchman'!A12:K1000,""where A is not null"");QUERY('#48 Andres Preza'!A12:K1000,""where A is not null"");QUERY('#49 Jahaziel Gala"&"n'!A12:K1000,""where A is not null"");QUERY('#51 Saul Murillo'!A12:K1000,""where A is not null"");QUERY('#52 Tommaso Rivetti'!A12:K1000,""where A is not null"");QUERY('#53 Monserrat Benitez'!A12:K1000,""where A is not null"");QUERY('#55 Gerardo Madrid'!A1"&"2:K1000,""where A is not null"");QUERY('#56 Carlos Ivan Gonzalez Merino'!A12:K1000,""where A is not null"");QUERY('#54 Mario Castorela'!A12:K1000,""where A is not null"");QUERY('#58 Jose Rosas'!A12:K1000,""where A is not null"");QUERY('#59 Mario Guadarram"&"a'!A12:K1000,""where A is not null"");QUERY('#60 Carlos Aleman'!A12:K1000,""where A is not null"");QUERY('#61 Jorge Diaz'!A12:K1000,""where A is not null"");QUERY('#62 Jorge Rojas'!A12:K1000,""where A is not null"");QUERY('#63 Diego Morodo'!A12:K1000,""wh"&"ere A is not null"");QUERY('#64 Erik Castillo'!A12:K1000,""where A is not null"");QUERY('#65 Diana Miranda'!A12:K1000,""where A is not null"");QUERY('#66 Jorge Ramirez'!A12:K1000,""where A is not null"");QUERY('#67 Gustavo Rivas'!A12:K1000,""where A is no"&"t null"");QUERY('#68 Alfonso Bello'!A12:K1000,""where A is not null"");QUERY('#69 Cole Anderson'!A12:K1000,""where A is not null"")}"),"TRX1286") -> TRX1286 | B2: =IFERROR(__xludf.DUMMYFUNCTION("""COMPUTED_VALUE"""),"#2") -> #2 | C2: =IFERROR(__xludf.DUMMYFUNCTION("""COMPUTED_VALUE"""),46056.4166666666) -> 46056.417 | D2: =IFERROR(__xludf.DUMMYFUNCTION("""COMPUTED_VALUE"""),3642.61) -> 3642.61 | E2: =IFERROR(__xludf.DUMMYFUNCTION("""COMPUTED_VALUE"""),"USD") -> USD | F2: =IFERROR(__xludf.DUMMYFUNCTION("""COMPUTED_VALUE"""),"Cesar Gonzales") -> Cesar Gonzales | G2: =IFERROR(__xludf.DUMMYFUNCTION("""COMPUTED_VALUE"""),"HASHICORP HCP SAN FRANCISCO USA") -> HASHICORP HCP SAN FRANCISCO USA | H2: =IFERROR(__xludf.DUMMYFUNCTION("""COMPUTED_VALUE"""),"Hashicorp") -> Hashicorp | I2: =IFERROR(__xludf.DUMMYFUNCTION("""COMPUTED_VALUE"""),"Tech&Product") -> Tech&Product | K2: =IFERROR(__xludf.DUMMYFUNCTION("""COMPUTED_VALUE"""),".") -> . | S2: 344.91 | T2: =VLOOKUP(S2,D:F,3,FALSE) -> #N/A | V2: #16 | W2: =VLOOKUP(V2,B:F,5,FALSE()) -> Rogelio Gamez
A3: =IFERROR(__xludf.DUMMYFUNCTION("""COMPUTED_VALUE"""),"TRX1246") -> TRX1246 | B3: =IFERROR(__xludf.DUMMYFUNCTION("""COMPUTED_VALUE"""),"#2") -> #2 | C3: =IFERROR(__xludf.DUMMYFUNCTION("""COMPUTED_VALUE"""),46058.4166666666) -> 46058.417 | D3: =IFERROR(__xludf.DUMMYFUNCTION("""COMPUTED_VALUE"""),15105.29) -> 15105.29 | E3: =IFERROR(__xludf.DUMMYFUNCTION("""COMPUTED_VALUE"""),"MXN") -> MXN | F3: =IFERROR(__xludf.DUMMYFUNCTION("""COMPUTED_VALUE"""),"Cesar Gonzales") -> Cesar Gonzales | G3: =IFERROR(__xludf.DUMMYFUNCTION("""COMPUTED_VALUE"""),"PAYU *GOOGLE CLOUD MIGUEL HIDALG MEX") -> PAYU *GOOGLE CLOUD MIGUEL HIDALG MEX | H3: =IFERROR(__xludf.DUMMYFUNCTION("""COMPUTED_VALUE"""),"Google Cloud") -> Google Cloud | I3: =IFERROR(__xludf.DUMMYFUNCTION("""COMPUTED_VALUE"""),"Tech&Product") -> Tech&Product | K3: =IFERROR(__xludf.DUMMYFUNCTION("""COMPUTED_VALUE"""),".") -> . | S3: 2802.46 | T3: =VLOOKUP(S3,D:F,3,FALSE) -> #N/A | V3: #2 | W3: =VLOOKUP(V3,B:F,5,FALSE()) -> Cesar Gonzales
A4: =IFERROR(__xludf.DUMMYFUNCTION("""COMPUTED_VALUE"""),"TRX1242") -> TRX1242 | B4: =IFERROR(__xludf.DUMMYFUNCTION("""COMPUTED_VALUE"""),"#2") -> #2 | C4: =IFERROR(__xludf.DUMMYFUNCTION("""COMPUTED_VALUE"""),46058.4166666666) -> 46058.417 | D4: =IFERROR(__xludf.DUMMYFUNCTION("""COMPUTED_VALUE"""),957.38) -> 957.38 | E4: =IFERROR(__xludf.DUMMYFUNCTION("""COMPUTED_VALUE"""),"MXN") -> MXN | F4: =IFERROR(__xludf.DUMMYFUNCTION("""COMPUTED_VALUE"""),"Cesar Gonzales") -> Cesar Gonzales | G4: =IFERROR(__xludf.DUMMYFUNCTION("""COMPUTED_VALUE"""),"PAYU *GOOGLE CLOUD MIGUEL HIDALG MEX") -> PAYU *GOOGLE CLOUD MIGUEL HIDALG MEX | H4: =IFERROR(__xludf.DUMMYFUNCTION("""COMPUTED_VALUE"""),"Google Cloud") -> Google Cloud | I4: =IFERROR(__xludf.DUMMYFUNCTION("""COMPUTED_VALUE"""),"Tech&Product") -> Tech&Product | K4: =IFERROR(__xludf.DUMMYFUNCTION("""COMPUTED_VALUE"""),".") -> . | S4: 69 | T4: =VLOOKUP(S4,D:F,3,FALSE) -> Rodrigo Perea | V4: #8 | W4: =VLOOKUP(V4,B:F,5,FALSE()) -> Jose Ignacio Martinez Flemate
A5: =IFERROR(__xludf.DUMMYFUNCTION("""COMPUTED_VALUE"""),"TRX1999") -> TRX1999 | B5: =IFERROR(__xludf.DUMMYFUNCTION("""COMPUTED_VALUE"""),"#2") -> #2 | C5: =IFERROR(__xludf.DUMMYFUNCTION("""COMPUTED_VALUE"""),46059.4173611111) -> 46059.417 | D5: =IFERROR(__xludf.DUMMYFUNCTION("""COMPUTED_VALUE"""),10214.06) -> 10214.06 | E5: =IFERROR(__xludf.DUMMYFUNCTION("""COMPUTED_VALUE"""),"USD") -> USD | F5: =IFERROR(__xludf.DUMMYFUNCTION("""COMPUTED_VALUE"""),"Cesar Gonzales") -> Cesar Gonzales | G5: =IFERROR(__xludf.DUMMYFUNCTION("""COMPUTED_VALUE"""),"GITHUB, INC. SAN FRANCISCO USA") -> GITHUB, INC. SAN FRANCISCO USA | H5: =IFERROR(__xludf.DUMMYFUNCTION("""COMPUTED_VALUE"""),"Github") -> Github | I5: =IFERROR(__xludf.DUMMYFUNCTION("""COMPUTED_VALUE"""),"Tech&Product") -> Tech&Product | K5: =IFERROR(__xludf.DUMMYFUNCTION("""COMPUTED_VALUE"""),".") -> . | S5: 79.94 | T5: =VLOOKUP(S5,D:F,3,FALSE) -> #N/A | V5: #60 | W5: =VLOOKUP(V5,B:F,5,FALSE()) -> #N/A
A6: =IFERROR(__xludf.DUMMYFUNCTION("""COMPUTED_VALUE"""),"TRX1875") -> TRX1875 | B6: =IFERROR(__xludf.DUMMYFUNCTION("""COMPUTED_VALUE"""),"#2") -> #2 | C6: =IFERROR(__xludf.DUMMYFUNCTION("""COMPUTED_VALUE"""),46063.4166666666) -> 46063.417 | D6: =IFERROR(__xludf.DUMMYFUNCTION("""COMPUTED_VALUE"""),6524.63) -> 6524.63 | E6: =IFERROR(__xludf.DUMMYFUNCTION("""COMPUTED_VALUE"""),"USD") -> USD | F6: =IFERROR(__xludf.DUMMYFUNCTION("""COMPUTED_VALUE"""),"Cesar Gonzales") -> Cesar Gonzales | G6: =IFERROR(__xludf.DUMMYFUNCTION("""COMPUTED_VALUE"""),"CURSOR, AI POWERED IDE NEW YORK USA") -> CURSOR, AI POWERED IDE NEW YORK USA | H6: =IFERROR(__xludf.DUMMYFUNCTION("""COMPUTED_VALUE"""),"Cursor Ai Powered Ide New York USA") -> Cursor Ai Powered Ide New York USA | I6: =IFERROR(__xludf.DUMMYFUNCTION("""COMPUTED_VALUE"""),"Tech&Product") -> Tech&Product | K6: =IFERROR(__xludf.DUMMYFUNCTION("""COMPUTED_VALUE"""),".") -> . | S6: 199.98 | T6: =VLOOKUP(S6,D:F,3,FALSE) -> #N/A | V6: #56 | W6: =VLOOKUP(V6,B:F,5,FALSE()) -> Carlos Ivan Gonzalez Merino
A7: =IFERROR(__xludf.DUMMYFUNCTION("""COMPUTED_VALUE"""),"TRX1596") -> TRX1596 | B7: =IFERROR(__xludf.DUMMYFUNCTION("""COMPUTED_VALUE"""),"#2") -> #2 | C7: =IFERROR(__xludf.DUMMYFUNCTION("""COMPUTED_VALUE"""),46065.4173611111) -> 46065.417 | D7: =IFERROR(__xludf.DUMMYFUNCTION("""COMPUTED_VALUE"""),906.2) -> 906.2 | E7: =IFERROR(__xludf.DUMMYFUNCTION("""COMPUTED_VALUE"""),"USD") -> USD | F7: =IFERROR(__xludf.DUMMYFUNCTION("""COMPUTED_VALUE"""),"Cesar Gonzales") -> Cesar Gonzales | G7: =IFERROR(__xludf.DUMMYFUNCTION("""COMPUTED_VALUE"""),"CURSOR USAGE JAN NEW YORK USA") -> CURSOR USAGE JAN NEW YORK USA | H7: =IFERROR(__xludf.DUMMYFUNCTION("""COMPUTED_VALUE"""),"Cursor Usage Jan New York USA") -> Cursor Usage Jan New York USA | I7: =IFERROR(__xludf.DUMMYFUNCTION("""COMPUTED_VALUE"""),"Tech&Product") -> Tech&Product | K7: =IFERROR(__xludf.DUMMYFUNCTION("""COMPUTED_VALUE"""),".") -> . | S7: 335.57 | T7: =VLOOKUP(S7,D:F,3,FALSE) -> #N/A | V7: #68 | W7: =VLOOKUP(V7,B:F,5,FALSE()) -> Jorge Armando Ramirez Perez
A8: =IFERROR(__xludf.DUMMYFUNCTION("""COMPUTED_VALUE"""),"TRX1641") -> TRX1641 | B8: =IFERROR(__xludf.DUMMYFUNCTION("""COMPUTED_VALUE"""),"#2") -> #2 | C8: =IFERROR(__xludf.DUMMYFUNCTION("""COMPUTED_VALUE"""),46065.4173611111) -> 46065.417 | D8: =IFERROR(__xludf.DUMMYFUNCTION("""COMPUTED_VALUE"""),7115.29) -> 7115.29 | E8: =IFERROR(__xludf.DUMMYFUNCTION("""COMPUTED_VALUE"""),"USD") -> USD | F8: =IFERROR(__xludf.DUMMYFUNCTION("""COMPUTED_VALUE"""),"Cesar Gonzales") -> Cesar Gonzales | G8: =IFERROR(__xludf.DUMMYFUNCTION("""COMPUTED_VALUE"""),"DATADOG, INC. NEW YORK USA") -> DATADOG, INC. NEW YORK USA | H8: =IFERROR(__xludf.DUMMYFUNCTION("""COMPUTED_VALUE"""),"Datadog") -> Datadog | I8: =IFERROR(__xludf.DUMMYFUNCTION("""COMPUTED_VALUE"""),"Tech&Product") -> Tech&Product | K8: =IFERROR(__xludf.DUMMYFUNCTION("""COMPUTED_VALUE"""),".") -> . | S8: 374.78 | T8: =VLOOKUP(S8,D:F,3,FALSE) -> #N/A | V8: #43 | W8: =VLOOKUP(V8,B:F,5,FALSE()) -> #N/A
A9: =IFERROR(__xludf.DUMMYFUNCTION("""COMPUTED_VALUE"""),"TRX1372") -> TRX1372 | B9: =IFERROR(__xludf.DUMMYFUNCTION("""COMPUTED_VALUE"""),"#2") -> #2 | C9: =IFERROR(__xludf.DUMMYFUNCTION("""COMPUTED_VALUE"""),46066.4166666666) -> 46066.417 | D9: =IFERROR(__xludf.DUMMYFUNCTION("""COMPUTED_VALUE"""),5964.72) -> 5964.72 | E9: =IFERROR(__xludf.DUMMYFUNCTION("""COMPUTED_VALUE"""),"MXN") -> MXN | F9: =IFERROR(__xludf.DUMMYFUNCTION("""COMPUTED_VALUE"""),"Cesar Gonzales") -> Cesar Gonzales | G9: =IFERROR(__xludf.DUMMYFUNCTION("""COMPUTED_VALUE"""),"STR*ODOO TECHNOLOGIES CIUDAD DE MEX MEX") -> STR*ODOO TECHNOLOGIES CIUDAD DE MEX MEX | H9: =IFERROR(__xludf.DUMMYFUNCTION("""COMPUTED_VALUE"""),"Str Odoo Technologies Ciudad De Mex Mex") -> Str Odoo Technologies Ciudad De Mex Mex | I9: =IFERROR(__xludf.DUMMYFUNCTION("""COMPUTED_VALUE"""),"Tech&Product") -> Tech&Product | K9: =IFERROR(__xludf.DUMMYFUNCTION("""COMPUTED_VALUE"""),".") -> . | S9: 33 | T9: =VLOOKUP(S9,D:F,3,FALSE) -> Erik Castillo | V9: #26 | W9: =VLOOKUP(V9,B:F,5,FALSE()) -> Karen Alexandra Ballesteros Contreras
A10: =IFERROR(__xludf.DUMMYFUNCTION("""COMPUTED_VALUE"""),"TRX1245") -> TRX1245 | B10: =IFERROR(__xludf.DUMMYFUNCTION("""COMPUTED_VALUE"""),"#2") -> #2 | C10: =IFERROR(__xludf.DUMMYFUNCTION("""COMPUTED_VALUE"""),46066.4173611111) -> 46066.417 | D10: =IFERROR(__xludf.DUMMYFUNCTION("""COMPUTED_VALUE"""),1083.21) -> 1083.21 | E10: =IFERROR(__xludf.DUMMYFUNCTION("""COMPUTED_VALUE"""),"USD") -> USD | F10: =IFERROR(__xludf.DUMMYFUNCTION("""COMPUTED_VALUE"""),"Cesar Gonzales") -> Cesar Gonzales | G10: =IFERROR(__xludf.DUMMYFUNCTION("""COMPUTED_VALUE"""),"AUGMENT CODE PALO ALTO USA") -> AUGMENT CODE PALO ALTO USA | H10: =IFERROR(__xludf.DUMMYFUNCTION("""COMPUTED_VALUE"""),"Augment Code Palo Alto USA") -> Augment Code Palo Alto USA | I10: =IFERROR(__xludf.DUMMYFUNCTION("""COMPUTED_VALUE"""),"Tech&Product") -> Tech&Product | K10: =IFERROR(__xludf.DUMMYFUNCTION("""COMPUTED_VALUE"""),".") -> . | S10: 4126.16 | T10: =VLOOKUP(S10,D:F,3,FALSE) -> #N/A | V10: #30 | W10: =VLOOKUP(V10,B:F,5,FALSE()) -> Manuel Ibarra Cebreros
A11: =IFERROR(__xludf.DUMMYFUNCTION("""COMPUTED_VALUE"""),"TRX1378") -> TRX1378 | B11: =IFERROR(__xludf.DUMMYFUNCTION("""COMPUTED_VALUE"""),"#2") -> #2 | C11: =IFERROR(__xludf.DUMMYFUNCTION("""COMPUTED_VALUE"""),46069.4166666666) -> 46069.417 | D11: =IFERROR(__xludf.DUMMYFUNCTION("""COMPUTED_VALUE"""),14399.42) -> 14399.42 | E11: =IFERROR(__xludf.DUMMYFUNCTION("""COMPUTED_VALUE"""),"USD") -> USD | F11: =IFERROR(__xludf.DUMMYFUNCTION("""COMPUTED_VALUE"""),"Cesar Gonzales") -> Cesar Gonzales | G11: =IFERROR(__xludf.DUMMYFUNCTION("""COMPUTED_VALUE"""),"AUTH0.COM SAN FRANCISCO USA") -> AUTH0.COM SAN FRANCISCO USA | H11: =IFERROR(__xludf.DUMMYFUNCTION("""COMPUTED_VALUE"""),"Auth0") -> Auth0 | I11: =IFERROR(__xludf.DUMMYFUNCTION("""COMPUTED_VALUE"""),"Tech&Product") -> Tech&Product | K11: =IFERROR(__xludf.DUMMYFUNCTION("""COMPUTED_VALUE"""),".") -> . | S11: 78 | T11: =VLOOKUP(S11,D:F,3,FALSE) -> Karen Alexandra Ballesteros Contreras | V11: #66 | W11: =VLOOKUP(V11,B:F,5,FALSE()) -> Erik Castillo
A12: =IFERROR(__xludf.DUMMYFUNCTION("""COMPUTED_VALUE"""),"TRX1821") -> TRX1821 | B12: =IFERROR(__xludf.DUMMYFUNCTION("""COMPUTED_VALUE"""),"#2") -> #2 | C12: =IFERROR(__xludf.DUMMYFUNCTION("""COMPUTED_VALUE"""),46073.4173611111) -> 46073.417 | D12: =IFERROR(__xludf.DUMMYFUNCTION("""COMPUTED_VALUE"""),471.63) -> 471.63 | E12: =IFERROR(__xludf.DUMMYFUNCTION("""COMPUTED_VALUE"""),"USD") -> USD | F12: =IFERROR(__xludf.DUMMYFUNCTION("""COMPUTED_VALUE"""),"Cesar Gonzales") -> Cesar Gonzales | G12: =IFERROR(__xludf.DUMMYFUNCTION("""COMPUTED_VALUE"""),"CURSOR, AI POWERED IDE NEW YORK USA") -> CURSOR, AI POWERED IDE NEW YORK USA | H12: =IFERROR(__xludf.DUMMYFUNCTION("""COMPUTED_VALUE"""),"Cursor Ai Powered Ide New York USA") -> Cursor Ai Powered Ide New York USA | I12: =IFERROR(__xludf.DUMMYFUNCTION("""COMPUTED_VALUE"""),"Tech&Product") -> Tech&Product | K12: =IFERROR(__xludf.DUMMYFUNCTION("""COMPUTED_VALUE"""),".") -> . | S12: 176.59 | T12: =VLOOKUP(S12,D:F,3,FALSE) -> #N/A | V12: #40 | W12: =VLOOKUP(V12,B:F,5,FALSE()) -> Gabriela Zacarias Aguirre
A13: =IFERROR(__xludf.DUMMYFUNCTION("""COMPUTED_VALUE"""),"TRX1080") -> TRX1080 | B13: =IFERROR(__xludf.DUMMYFUNCTION("""COMPUTED_VALUE"""),"#2") -> #2 | C13: =IFERROR(__xludf.DUMMYFUNCTION("""COMPUTED_VALUE"""),46075.4173611111) -> 46075.417 | D13: =IFERROR(__xludf.DUMMYFUNCTION("""COMPUTED_VALUE"""),2619.98) -> 2619.98 | E13: =IFERROR(__xludf.DUMMYFUNCTION("""COMPUTED_VALUE"""),"USD") -> USD | F13: =IFERROR(__xludf.DUMMYFUNCTION("""COMPUTED_VALUE"""),"Cesar Gonzales") -> Cesar Gonzales | G13: =IFERROR(__xludf.DUMMYFUNCTION("""COMPUTED_VALUE"""),"ATLASSIAN SAN FRANCISCO USA") -> ATLASSIAN SAN FRANCISCO USA | H13: =IFERROR(__xludf.DUMMYFUNCTION("""COMPUTED_VALUE"""),"Atlassian") -> Atlassian | I13: =IFERROR(__xludf.DUMMYFUNCTION("""COMPUTED_VALUE"""),"Tech&Product") -> Tech&Product | K13: =IFERROR(__xludf.DUMMYFUNCTION("""COMPUTED_VALUE"""),".") -> . | S13: 152 | T13: =VLOOKUP(S13,D:F,3,FALSE) -> #N/A | V13: #53 | W13: =VLOOKUP(V13,B:F,5,FALSE()) -> Monserrat Benitez
A14: =IFERROR(__xludf.DUMMYFUNCTION("""COMPUTED_VALUE"""),"TRX1119") -> TRX1119 | B14: =IFERROR(__xludf.DUMMYFUNCTION("""COMPUTED_VALUE"""),"#2") -> #2 | C14: =IFERROR(__xludf.DUMMYFUNCTION("""COMPUTED_VALUE"""),46077.4166666666) -> 46077.417 | D14: =IFERROR(__xludf.DUMMYFUNCTION("""COMPUTED_VALUE"""),3853.97) -> 3853.97 | E14: =IFERROR(__xludf.DUMMYFUNCTION("""COMPUTED_VALUE"""),"USD") -> USD | F14: =IFERROR(__xludf.DUMMYFUNCTION("""COMPUTED_VALUE"""),"Cesar Gonzales") -> Cesar Gonzales | G14: =IFERROR(__xludf.DUMMYFUNCTION("""COMPUTED_VALUE"""),"RETOOL SAN FRANCISCO USA") -> RETOOL SAN FRANCISCO USA | H14: =IFERROR(__xludf.DUMMYFUNCTION("""COMPUTED_VALUE"""),"Retool") -> Retool | I14: =IFERROR(__xludf.DUMMYFUNCTION("""COMPUTED_VALUE"""),"Tech&Product") -> Tech&Product | K14: =IFERROR(__xludf.DUMMYFUNCTION("""COMPUTED_VALUE"""),".") -> . | S14: 99 | T14: =VLOOKUP(S14,D:F,3,FALSE) -> #N/A | V14: #67 | W14: =VLOOKUP(V14,B:F,5,FALSE()) -> #N/A
A15: =IFERROR(__xludf.DUMMYFUNCTION("""COMPUTED_VALUE"""),"TRX1124") -> TRX1124 | B15: =IFERROR(__xludf.DUMMYFUNCTION("""COMPUTED_VALUE"""),"#2") -> #2 | C15: =IFERROR(__xludf.DUMMYFUNCTION("""COMPUTED_VALUE"""),46077.4166666666) -> 46077.417 | D15: =IFERROR(__xludf.DUMMYFUNCTION("""COMPUTED_VALUE"""),8235.56) -> 8235.56 | E15: =IFERROR(__xludf.DUMMYFUNCTION("""COMPUTED_VALUE"""),"USD") -> USD | F15: =IFERROR(__xludf.DUMMYFUNCTION("""COMPUTED_VALUE"""),"Cesar Gonzales") -> Cesar Gonzales | G15: =IFERROR(__xludf.DUMMYFUNCTION("""COMPUTED_VALUE"""),"METABASE INC SPRING VALLEY USA") -> METABASE INC SPRING VALLEY USA | H15: =IFERROR(__xludf.DUMMYFUNCTION("""COMPUTED_VALUE"""),"Metabase") -> Metabase | I15: =IFERROR(__xludf.DUMMYFUNCTION("""COMPUTED_VALUE"""),"Tech&Product") -> Tech&Product | K15: =IFERROR(__xludf.DUMMYFUNCTION("""COMPUTED_VALUE"""),".") -> . | S15: 102 | T15: =VLOOKUP(S15,D:F,3,FALSE) -> #N/A | V15: #9 | W15: =VLOOKUP(V15,B:F,5,FALSE()) -> Jose Maria Garcia Hernandez
A16: =IFERROR(__xludf.DUMMYFUNCTION("""COMPUTED_VALUE"""),"TRX1127") -> TRX1127 | B16: =IFERROR(__xludf.DUMMYFUNCTION("""COMPUTED_VALUE"""),"#2") -> #2 | C16: =IFERROR(__xludf.DUMMYFUNCTION("""COMPUTED_VALUE"""),46077.4166666666) -> 46077.417 | D16: =IFERROR(__xludf.DUMMYFUNCTION("""COMPUTED_VALUE"""),7106.33) -> 7106.33 | E16: =IFERROR(__xludf.DUMMYFUNCTION("""COMPUTED_VALUE"""),"USD") -> USD | F16: =IFERROR(__xludf.DUMMYFUNCTION("""COMPUTED_VALUE"""),"Cesar Gonzales") -> Cesar Gonzales | G16: =IFERROR(__xludf.DUMMYFUNCTION("""COMPUTED_VALUE"""),"Microsoft-G142443073 msbill.info USA") -> Microsoft-G142443073 msbill.info USA | H16: =IFERROR(__xludf.DUMMYFUNCTION("""COMPUTED_VALUE"""),"Microsoft") -> Microsoft | I16: =IFERROR(__xludf.DUMMYFUNCTION("""COMPUTED_VALUE"""),"Tech&Product") -> Tech&Product | K16: =IFERROR(__xludf.DUMMYFUNCTION("""COMPUTED_VALUE"""),".") -> . | S16: 5296 | T16: =VLOOKUP(S16,D:F,3,FALSE) -> #N/A | V16: #13 | W16: =VLOOKUP(V16,B:F,5,FALSE()) -> Miguel De Lascurain
A17: =IFERROR(__xludf.DUMMYFUNCTION("""COMPUTED_VALUE"""),"TRX1239") -> TRX1239 | B17: =IFERROR(__xludf.DUMMYFUNCTION("""COMPUTED_VALUE"""),"#3") -> #3 | C17: =IFERROR(__xludf.DUMMYFUNCTION("""COMPUTED_VALUE"""),46058.4166666666) -> 46058.417 | D17: =IFERROR(__xludf.DUMMYFUNCTION("""COMPUTED_VALUE"""),1130) -> 1130 | E17: =IFERROR(__xludf.DUMMYFUNCTION("""COMPUTED_VALUE"""),"MXN") -> MXN | F17: =IFERROR(__xludf.DUMMYFUNCTION("""COMPUTED_VALUE"""),"Cesar Uriel Romo Trillo") -> Cesar Uriel Romo Trillo | G17: =IFERROR(__xludf.DUMMYFUNCTION("""COMPUTED_VALUE"""),"HAMMER STRONG CIUDAD DE MEX MEX") -> HAMMER STRONG CIUDAD DE MEX MEX | H17: =IFERROR(__xludf.DUMMYFUNCTION("""COMPUTED_VALUE"""),"Hammer Strong Ciudad De Mex Mex") -> Hammer Strong Ciudad De Mex Mex | I17: =IFERROR(__xludf.DUMMYFUNCTION("""COMPUTED_VALUE"""),"Sales") -> Sales | J17: =IFERROR(__xludf.DUMMYFUNCTION("""COMPUTED_VALUE"""),"Compra de Pulidora y discos para obra Grajales Robles PO1129") -> Compra de Pulidora y discos para obra Grajales Robles PO1129 | K17: =IFERROR(__xludf.DUMMYFUNCTION("""COMPUTED_VALUE"""),"TICKET") -> TICKET | S17: 102 | T17: =VLOOKUP(S17,D:F,3,FALSE) -> #N/A | V17: #64 | W17: =VLOOKUP(V17,B:F,5,FALSE()) -> Jorge Rojas
A18: =IFERROR(__xludf.DUMMYFUNCTION("""COMPUTED_VALUE"""),"TRX1151") -> TRX1151 | B18: =IFERROR(__xludf.DUMMYFUNCTION("""COMPUTED_VALUE"""),"#3") -> #3 | C18: =IFERROR(__xludf.DUMMYFUNCTION("""COMPUTED_VALUE"""),46059.4173611111) -> 46059.417 | D18: =IFERROR(__xludf.DUMMYFUNCTION("""COMPUTED_VALUE"""),344.25) -> 344.25 | E18: =IFERROR(__xludf.DUMMYFUNCTION("""COMPUTED_VALUE"""),"MXN") -> MXN | F18: =IFERROR(__xludf.DUMMYFUNCTION("""COMPUTED_VALUE"""),"Cesar Uriel Romo Trillo") -> Cesar Uriel Romo Trillo | G18: =IFERROR(__xludf.DUMMYFUNCTION("""COMPUTED_VALUE"""),"GAS JUVITA MEXICO DF MEX") -> GAS JUVITA MEXICO DF MEX | H18: =IFERROR(__xludf.DUMMYFUNCTION("""COMPUTED_VALUE"""),"Gas Juvita Mexico Df Mex") -> Gas Juvita Mexico Df Mex | I18: =IFERROR(__xludf.DUMMYFUNCTION("""COMPUTED_VALUE"""),"Sales") -> Sales | J18: =IFERROR(__xludf.DUMMYFUNCTION("""COMPUTED_VALUE"""),"Gasolina visita desmontaje de Grua Grajales Robles PO1129") -> Gasolina visita desmontaje de Grua Grajales Robles PO1129 | K18: =IFERROR(__xludf.DUMMYFUNCTION("""COMPUTED_VALUE"""),"TICKET") -> TICKET | S18: 12818 | T18: =VLOOKUP(S18,D:F,3,FALSE) -> #N/A | V18: #71 | W18: =VLOOKUP(V18,B:F,5,FALSE()) -> #N/A
A19: =IFERROR(__xludf.DUMMYFUNCTION("""COMPUTED_VALUE"""),"TRX1538") -> TRX1538 | B19: =IFERROR(__xludf.DUMMYFUNCTION("""COMPUTED_VALUE"""),"#3") -> #3 | C19: =IFERROR(__xludf.DUMMYFUNCTION("""COMPUTED_VALUE"""),46060.4173611111) -> 46060.417 | D19: =IFERROR(__xludf.DUMMYFUNCTION("""COMPUTED_VALUE"""),803.6) -> 803.6 | E19: =IFERROR(__xludf.DUMMYFUNCTION("""COMPUTED_VALUE"""),"MXN") -> MXN | F19: =IFERROR(__xludf.DUMMYFUNCTION("""COMPUTED_VALUE"""),"Cesar Uriel Romo Trillo") -> Cesar Uriel Romo Trillo | G19: =IFERROR(__xludf.DUMMYFUNCTION("""COMPUTED_VALUE"""),"GASOLINERA COMB ERMITA CIUDAD DE MEX MEX") -> GASOLINERA COMB ERMITA CIUDAD DE MEX MEX | H19: =IFERROR(__xludf.DUMMYFUNCTION("""COMPUTED_VALUE"""),"Gasolinera Comb Ermita Ciudad De Mex Mex") -> Gasolinera Comb Ermita Ciudad De Mex Mex | I19: =IFERROR(__xludf.DUMMYFUNCTION("""COMPUTED_VALUE"""),"Sales") -> Sales | J19: =IFERROR(__xludf.DUMMYFUNCTION("""COMPUTED_VALUE"""),"Gasolina para Malacate Grajales Robles PO 1129") -> Gasolina para Malacate Grajales Robles PO 1129 | K19: =IFERROR(__xludf.DUMMYFUNCTION("""COMPUTED_VALUE"""),"TICKET") -> TICKET | S19: 173.12 | T19: =VLOOKUP(S19,D:F,3,FALSE) -> #N/A | V19: #28 | W19: =VLOOKUP(V19,B:F,5,FALSE()) -> Fernando Villalobos Lara
A20: =IFERROR(__xludf.DUMMYFUNCTION("""COMPUTED_VALUE"""),"TRX1068") -> TRX1068 | B20: =IFERROR(__xludf.DUMMYFUNCTION("""COMPUTED_VALUE"""),"#3") -> #3 | C20: =IFERROR(__xludf.DUMMYFUNCTION("""COMPUTED_VALUE"""),46065.4173611111) -> 46065.417 | D20: =IFERROR(__xludf.DUMMYFUNCTION("""COMPUTED_VALUE"""),574) -> 574 | E20: =IFERROR(__xludf.DUMMYFUNCTION("""COMPUTED_VALUE"""),"MXN") -> MXN | F20: =IFERROR(__xludf.DUMMYFUNCTION("""COMPUTED_VALUE"""),"Cesar Uriel Romo Trillo") -> Cesar Uriel Romo Trillo | G20: =IFERROR(__xludf.DUMMYFUNCTION("""COMPUTED_VALUE"""),"GASOLINERA COMB ERMITA CIUDAD DE MEX MEX") -> GASOLINERA COMB ERMITA CIUDAD DE MEX MEX | H20: =IFERROR(__xludf.DUMMYFUNCTION("""COMPUTED_VALUE"""),"Gasolinera Comb Ermita Ciudad De Mex Mex") -> Gasolinera Comb Ermita Ciudad De Mex Mex | I20: =IFERROR(__xludf.DUMMYFUNCTION("""COMPUTED_VALUE"""),"Sales") -> Sales | J20: =IFERROR(__xludf.DUMMYFUNCTION("""COMPUTED_VALUE"""),"Gasolina visita equipo Elvic PO1129") -> Gasolina visita equipo Elvic PO1129 | K20: =IFERROR(__xludf.DUMMYFUNCTION("""COMPUTED_VALUE"""),"TICKET") -> TICKET | S20: 70 | T20: =VLOOKUP(S20,D:F,3,FALSE) -> Fernanda Sanchez Ruiz | V20: #41 | W20: =VLOOKUP(V20,B:F,5,FALSE()) -> Jose Arechavala
A21: =IFERROR(__xludf.DUMMYFUNCTION("""COMPUTED_VALUE"""),"TRX1608") -> TRX1608 | B21: =IFERROR(__xludf.DUMMYFUNCTION("""COMPUTED_VALUE"""),"#3") -> #3 | C21: =IFERROR(__xludf.DUMMYFUNCTION("""COMPUTED_VALUE"""),46065.4173611111) -> 46065.417 | D21: =IFERROR(__xludf.DUMMYFUNCTION("""COMPUTED_VALUE"""),767) -> 767 | E21: =IFERROR(__xludf.DUMMYFUNCTION("""COMPUTED_VALUE"""),"MXN") -> MXN | F21: =IFERROR(__xludf.DUMMYFUNCTION("""COMPUTED_VALUE"""),"Cesar Uriel Romo Trillo") -> Cesar Uriel Romo Trillo | G21: =IFERROR(__xludf.DUMMYFUNCTION("""COMPUTED_VALUE"""),"MAMA S PIZZA CIUDAD DE MEX MEX") -> MAMA S PIZZA CIUDAD DE MEX MEX | H21: =IFERROR(__xludf.DUMMYFUNCTION("""COMPUTED_VALUE"""),"Mama S Pizza Ciudad De Mex Mex") -> Mama S Pizza Ciudad De Mex Mex | I21: =IFERROR(__xludf.DUMMYFUNCTION("""COMPUTED_VALUE"""),"Sales") -> Sales | J21: =IFERROR(__xludf.DUMMYFUNCTION("""COMPUTED_VALUE"""),"Comida equipo Elvic PO 1129") -> Comida equipo Elvic PO 1129 | K21: =IFERROR(__xludf.DUMMYFUNCTION("""COMPUTED_VALUE"""),"TICKET") -> TICKET | S21: 309 | T21: =VLOOKUP(S21,D:F,3,FALSE) -> #N/A | V21: #51 | W21: =VLOOKUP(V21,B:F,5,FALSE()) -> #N/A
A22: =IFERROR(__xludf.DUMMYFUNCTION("""COMPUTED_VALUE"""),"TRX1618") -> TRX1618 | B22: =IFERROR(__xludf.DUMMYFUNCTION("""COMPUTED_VALUE"""),"#3") -> #3 | C22: =IFERROR(__xludf.DUMMYFUNCTION("""COMPUTED_VALUE"""),46071.4173611111) -> 46071.417 | D22: =IFERROR(__xludf.DUMMYFUNCTION("""COMPUTED_VALUE"""),918.4) -> 918.4 | E22: =IFERROR(__xludf.DUMMYFUNCTION("""COMPUTED_VALUE"""),"MXN") -> MXN | F22: =IFERROR(__xludf.DUMMYFUNCTION("""COMPUTED_VALUE"""),"Cesar Uriel Romo Trillo") -> Cesar Uriel Romo Trillo | G22: =IFERROR(__xludf.DUMMYFUNCTION("""COMPUTED_VALUE"""),"GASOLINERA COMB ERMITA CIUDAD DE MEX MEX") -> GASOLINERA COMB ERMITA CIUDAD DE MEX MEX | H22: =IFERROR(__xludf.DUMMYFUNCTION("""COMPUTED_VALUE"""),"Gasolinera Comb Ermita Ciudad De Mex Mex") -> Gasolinera Comb Ermita Ciudad De Mex Mex | I22: =IFERROR(__xludf.DUMMYFUNCTION("""COMPUTED_VALUE"""),"Sales") -> Sales | J22: =IFERROR(__xludf.DUMMYFUNCTION("""COMPUTED_VALUE"""),"Gasolina Visita deal nuevo Grupo GSA") -> Gasolina Visita deal nuevo Grupo GSA | K22: =IFERROR(__xludf.DUMMYFUNCTION("""COMPUTED_VALUE"""),"TICKET") -> TICKET | S22: 14141.37 | T22: =VLOOKUP(S22,D:F,3,FALSE) -> #N/A | V22: #55 | W22: =VLOOKUP(V22,B:F,5,FALSE()) -> Gerardo Madrid
A23: =IFERROR(__xludf.DUMMYFUNCTION("""COMPUTED_VALUE"""),"TRX1068") -> TRX1068 | B23: =IFERROR(__xludf.DUMMYFUNCTION("""COMPUTED_VALUE"""),"#3") -> #3 | C23: =IFERROR(__xludf.DUMMYFUNCTION("""COMPUTED_VALUE"""),46075.4166666666) -> 46075.417 | D23: =IFERROR(__xludf.DUMMYFUNCTION("""COMPUTED_VALUE"""),344.4) -> 344.4 | E23: =IFERROR(__xludf.DUMMYFUNCTION("""COMPUTED_VALUE"""),"MXN") -> MXN | F23: =IFERROR(__xludf.DUMMYFUNCTION("""COMPUTED_VALUE"""),"Cesar Uriel Romo Trillo") -> Cesar Uriel Romo Trillo | G23: =IFERROR(__xludf.DUMMYFUNCTION("""COMPUTED_VALUE"""),"COMBUSTIBLE ERMITA CIUDAD DE MEX MEX") -> COMBUSTIBLE ERMITA CIUDAD DE MEX MEX | H23: =IFERROR(__xludf.DUMMYFUNCTION("""COMPUTED_VALUE"""),"Combustible Ermita Ciudad De Mex Mex") -> Combustible Ermita Ciudad De Mex Mex | I23: =IFERROR(__xludf.DUMMYFUNCTION("""COMPUTED_VALUE"""),"Sales") -> Sales | J23: =IFERROR(__xludf.DUMMYFUNCTION("""COMPUTED_VALUE"""),"Gasolina Visita Grajales Robles PO 1129, visita obra Parque Churubusco (nuevo deal), Visita Syvasa Calidad RFQ 3254 ") -> Gasolina Visita Grajales Robles PO 1129, visita obra Parque Churubusco (nuevo deal), Visita Syvasa Calidad RFQ 3254 | K23: =IFERROR(__xludf.DUMMYFUNCTION("""COMPUTED_VALUE"""),"TICKET") -> TICKET | S23: 211.71 | T23: =VLOOKUP(S23,D:F,3,FALSE) -> #N/A | V23: #19 | W23: =VLOOKUP(V23,B:F,5,FALSE()) -> Daniel Alejandro Castillo Rivera
A24: =IFERROR(__xludf.DUMMYFUNCTION("""COMPUTED_VALUE"""),"TRX1098") -> TRX1098 | B24: =IFERROR(__xludf.DUMMYFUNCTION("""COMPUTED_VALUE"""),"#3") -> #3 | C24: =IFERROR(__xludf.DUMMYFUNCTION("""COMPUTED_VALUE"""),46076.4166666666) -> 46076.417 | D24: =IFERROR(__xludf.DUMMYFUNCTION("""COMPUTED_VALUE"""),142.19) -> 142.19 | E24: =IFERROR(__xludf.DUMMYFUNCTION("""COMPUTED_VALUE"""),"MXN") -> MXN | F24: =IFERROR(__xludf.DUMMYFUNCTION("""COMPUTED_VALUE"""),"Cesar Uriel Romo Trillo") -> Cesar Uriel Romo Trillo | G24: =IFERROR(__xludf.DUMMYFUNCTION("""COMPUTED_VALUE"""),"D LOCAL*REST DIDIFOOD CIUDAD DE MEX MEX") -> D LOCAL*REST DIDIFOOD CIUDAD DE MEX MEX | H24: =IFERROR(__xludf.DUMMYFUNCTION("""COMPUTED_VALUE"""),"D Local Rest Didifood Ciudad De Mex Mex") -> D Local Rest Didifood Ciudad De Mex Mex | I24: =IFERROR(__xludf.DUMMYFUNCTION("""COMPUTED_VALUE"""),"Sales") -> Sales | J24: =IFERROR(__xludf.DUMMYFUNCTION("""COMPUTED_VALUE"""),"Compra de candado GRAJALES ROBLES PO 1129") -> Compra de candado GRAJALES ROBLES PO 1129 | K24: =IFERROR(__xludf.DUMMYFUNCTION("""COMPUTED_VALUE"""),"TICKET") -> TICKET | S24: 217.63 | T24: =VLOOKUP(S24,D:F,3,FALSE) -> #N/A | V24: #31 | W24: =VLOOKUP(V24,B:F,5,FALSE()) -> Emiliano Cavazos
A25: =IFERROR(__xludf.DUMMYFUNCTION("""COMPUTED_VALUE"""),"TRX1288") -> TRX1288 | B25: =IFERROR(__xludf.DUMMYFUNCTION("""COMPUTED_VALUE"""),"#4") -> #4 | C25: =IFERROR(__xludf.DUMMYFUNCTION("""COMPUTED_VALUE"""),46056.4166666666) -> 46056.417 | D25: =IFERROR(__xludf.DUMMYFUNCTION("""COMPUTED_VALUE"""),915.4) -> 915.4 | E25: =IFERROR(__xludf.DUMMYFUNCTION("""COMPUTED_VALUE"""),"MXN") -> MXN | F25: =IFERROR(__xludf.DUMMYFUNCTION("""COMPUTED_VALUE"""),"Daniel Autrique Echeveste") -> Daniel Autrique Echeveste | G25: =IFERROR(__xludf.DUMMYFUNCTION("""COMPUTED_VALUE"""),"LPQ AICM T1 SALA 8 1 CIUDAD DE MEX MEX") -> LPQ AICM T1 SALA 8 1 CIUDAD DE MEX MEX | H25: =IFERROR(__xludf.DUMMYFUNCTION("""COMPUTED_VALUE"""),"L") -> L | I25: =IFERROR(__xludf.DUMMYFUNCTION("""COMPUTED_VALUE"""),"Recruiting") -> Recruiting | J25: =IFERROR(__xludf.DUMMYFUNCTION("""COMPUTED_VALUE"""),"LinkedIn") -> LinkedIn | K25: =IFERROR(__xludf.DUMMYFUNCTION("""COMPUTED_VALUE"""),".") -> . | S25: 314.35 | T25: =VLOOKUP(S25,D:F,3,FALSE) -> #N/A | V25: #24 | W25: =VLOOKUP(V25,B:F,5,FALSE()) -> Andres Camacho Herrera
A26: =IFERROR(__xludf.DUMMYFUNCTION("""COMPUTED_VALUE"""),"TRX1279") -> TRX1279 | B26: =IFERROR(__xludf.DUMMYFUNCTION("""COMPUTED_VALUE"""),"#4") -> #4 | C26: =IFERROR(__xludf.DUMMYFUNCTION("""COMPUTED_VALUE"""),46056.4166666666) -> 46056.417 | D26: =IFERROR(__xludf.DUMMYFUNCTION("""COMPUTED_VALUE"""),704.7) -> 704.7 | E26: =IFERROR(__xludf.DUMMYFUNCTION("""COMPUTED_VALUE"""),"USD") -> USD | F26: =IFERROR(__xludf.DUMMYFUNCTION("""COMPUTED_VALUE"""),"Daniel Autrique Echeveste") -> Daniel Autrique Echeveste | G26: =IFERROR(__xludf.DUMMYFUNCTION("""COMPUTED_VALUE"""),"CURB MOBILITY ASTORIA USA") -> CURB MOBILITY ASTORIA USA | H26: =IFERROR(__xludf.DUMMYFUNCTION("""COMPUTED_VALUE"""),"Curb Mobility") -> Curb Mobility | I26: =IFERROR(__xludf.DUMMYFUNCTION("""COMPUTED_VALUE"""),"Sales") -> Sales | J26: =IFERROR(__xludf.DUMMYFUNCTION("""COMPUTED_VALUE"""),"Vuelo a chicago Radioflyer") -> Vuelo a chicago Radioflyer | K26: =IFERROR(__xludf.DUMMYFUNCTION("""COMPUTED_VALUE"""),".") -> . | S26: 492.45 | T26: =VLOOKUP(S26,D:F,3,FALSE) -> #N/A | V26: #52 | W26: =VLOOKUP(V26,B:F,5,FALSE()) -> Tommaso Rivetti Vinea
A27: =IFERROR(__xludf.DUMMYFUNCTION("""COMPUTED_VALUE"""),"TRX1272") -> TRX1272 | B27: =IFERROR(__xludf.DUMMYFUNCTION("""COMPUTED_VALUE"""),"#4") -> #4 | C27: =IFERROR(__xludf.DUMMYFUNCTION("""COMPUTED_VALUE"""),46057.4166666666) -> 46057.417 | D27: =IFERROR(__xludf.DUMMYFUNCTION("""COMPUTED_VALUE"""),1216.2) -> 1216.2 | E27: =IFERROR(__xludf.DUMMYFUNCTION("""COMPUTED_VALUE"""),"USD") -> USD | F27: =IFERROR(__xludf.DUMMYFUNCTION("""COMPUTED_VALUE"""),"Daniel Autrique Echeveste") -> Daniel Autrique Echeveste | G27: =IFERROR(__xludf.DUMMYFUNCTION("""COMPUTED_VALUE"""),"TCOLV - Naughty Patt LAS VEGAS USA") -> TCOLV - Naughty Patt LAS VEGAS USA | H27: =IFERROR(__xludf.DUMMYFUNCTION("""COMPUTED_VALUE"""),"Tcolv Naughty Patt Las Vegas USA") -> Tcolv Naughty Patt Las Vegas USA | I27: =IFERROR(__xludf.DUMMYFUNCTION("""COMPUTED_VALUE"""),"Sales") -> Sales | K27: =IFERROR(__xludf.DUMMYFUNCTION("""COMPUTED_VALUE"""),".") -> . | S27: 69 | T27: =VLOOKUP(S27,D:F,3,FALSE) -> Rodrigo Perea | V27: #69 | W27: =VLOOKUP(V27,B:F,5,FALSE()) -> Gustavo Rivas
A28: =IFERROR(__xludf.DUMMYFUNCTION("""COMPUTED_VALUE"""),"TRX1271") -> TRX1271 | B28: =IFERROR(__xludf.DUMMYFUNCTION("""COMPUTED_VALUE"""),"#4") -> #4 | C28: =IFERROR(__xludf.DUMMYFUNCTION("""COMPUTED_VALUE"""),46057.4166666666) -> 46057.417 | D28: =IFERROR(__xludf.DUMMYFUNCTION("""COMPUTED_VALUE"""),476.1) -> 476.1 | E28: =IFERROR(__xludf.DUMMYFUNCTION("""COMPUTED_VALUE"""),"USD") -> USD | F28: =IFERROR(__xludf.DUMMYFUNCTION("""COMPUTED_VALUE"""),"Daniel Autrique Echeveste") -> Daniel Autrique Echeveste | G28: =IFERROR(__xludf.DUMMYFUNCTION("""COMPUTED_VALUE"""),"ZTRIP TAXI KANSAS CITY USA") -> ZTRIP TAXI KANSAS CITY USA | H28: =IFERROR(__xludf.DUMMYFUNCTION("""COMPUTED_VALUE"""),"Ztrip Taxi Kansas City USA") -> Ztrip Taxi Kansas City USA | I28: =IFERROR(__xludf.DUMMYFUNCTION("""COMPUTED_VALUE"""),"Sales") -> Sales | K28: =IFERROR(__xludf.DUMMYFUNCTION("""COMPUTED_VALUE"""),".") -> . | S28: 392.61 | T28: =VLOOKUP(S28,D:F,3,FALSE) -> #N/A | V28: #46 | W28: =VLOOKUP(V28,B:F,5,FALSE()) -> #N/A
A29: =IFERROR(__xludf.DUMMYFUNCTION("""COMPUTED_VALUE"""),"TRX1197") -> TRX1197 | B29: =IFERROR(__xludf.DUMMYFUNCTION("""COMPUTED_VALUE"""),"#4") -> #4 | C29: =IFERROR(__xludf.DUMMYFUNCTION("""COMPUTED_VALUE"""),46058.4173611111) -> 46058.417 | D29: =IFERROR(__xludf.DUMMYFUNCTION("""COMPUTED_VALUE"""),11358) -> 11358 | E29: =IFERROR(__xludf.DUMMYFUNCTION("""COMPUTED_VALUE"""),"USD") -> USD | F29: =IFERROR(__xludf.DUMMYFUNCTION("""COMPUTED_VALUE"""),"Daniel Autrique Echeveste") -> Daniel Autrique Echeveste | G29: =IFERROR(__xludf.DUMMYFUNCTION("""COMPUTED_VALUE"""),"WOLFGANG PUCK CUT LAS VEGAS USA") -> WOLFGANG PUCK CUT LAS VEGAS USA | H29: =IFERROR(__xludf.DUMMYFUNCTION("""COMPUTED_VALUE"""),"Wolfgang Puck") -> Wolfgang Puck | I29: =IFERROR(__xludf.DUMMYFUNCTION("""COMPUTED_VALUE"""),"G&A expenses") -> G&A expenses | K29: =IFERROR(__xludf.DUMMYFUNCTION("""COMPUTED_VALUE"""),".") -> . | S29: 5175.02 | T29: =VLOOKUP(S29,D:F,3,FALSE) -> #N/A | V29: #37 | W29: =VLOOKUP(V29,B:F,5,FALSE()) -> #N/A
A30: =IFERROR(__xludf.DUMMYFUNCTION("""COMPUTED_VALUE"""),"TRX1193") -> TRX1193 | B30: =IFERROR(__xludf.DUMMYFUNCTION("""COMPUTED_VALUE"""),"#4") -> #4 | C30: =IFERROR(__xludf.DUMMYFUNCTION("""COMPUTED_VALUE"""),46058.4180555555) -> 46058.418 | D30: =IFERROR(__xludf.DUMMYFUNCTION("""COMPUTED_VALUE"""),181.58) -> 181.58 | E30: =IFERROR(__xludf.DUMMYFUNCTION("""COMPUTED_VALUE"""),"USD") -> USD | F30: =IFERROR(__xludf.DUMMYFUNCTION("""COMPUTED_VALUE"""),"Daniel Autrique Echeveste") -> Daniel Autrique Echeveste | G30: =IFERROR(__xludf.DUMMYFUNCTION("""COMPUTED_VALUE"""),"Viasat, Inc. 8669453258 USA") -> Viasat, Inc. 8669453258 USA | H30: =IFERROR(__xludf.DUMMYFUNCTION("""COMPUTED_VALUE"""),"Viasat") -> Viasat | I30: =IFERROR(__xludf.DUMMYFUNCTION("""COMPUTED_VALUE"""),"Sales") -> Sales | K30: =IFERROR(__xludf.DUMMYFUNCTION("""COMPUTED_VALUE"""),".") -> . | S30: 2527.29 | T30: =VLOOKUP(S30,D:F,3,FALSE) -> #N/A | V30: #34 | W30: =VLOOKUP(V30,B:F,5,FALSE()) -> Juan Pablo Ramos Aranda
A31: =IFERROR(__xludf.DUMMYFUNCTION("""COMPUTED_VALUE"""),"TRX1576") -> TRX1576 | B31: =IFERROR(__xludf.DUMMYFUNCTION("""COMPUTED_VALUE"""),"#4") -> #4 | C31: =IFERROR(__xludf.DUMMYFUNCTION("""COMPUTED_VALUE"""),46059.4173611111) -> 46059.417 | D31: =IFERROR(__xludf.DUMMYFUNCTION("""COMPUTED_VALUE"""),13052.62) -> 13052.62 | E31: =IFERROR(__xludf.DUMMYFUNCTION("""COMPUTED_VALUE"""),"MXN") -> MXN | F31: =IFERROR(__xludf.DUMMYFUNCTION("""COMPUTED_VALUE"""),"Daniel Autrique Echeveste") -> Daniel Autrique Echeveste | G31: =IFERROR(__xludf.DUMMYFUNCTION("""COMPUTED_VALUE"""),"COSMOPOL-FRONT DESK LAS VEGAS USA") -> COSMOPOL-FRONT DESK LAS VEGAS USA | H31: =IFERROR(__xludf.DUMMYFUNCTION("""COMPUTED_VALUE"""),"Cosmopol Front Desk Las Vegas USA") -> Cosmopol Front Desk Las Vegas USA | I31: =IFERROR(__xludf.DUMMYFUNCTION("""COMPUTED_VALUE"""),"Sales") -> Sales | K31: =IFERROR(__xludf.DUMMYFUNCTION("""COMPUTED_VALUE"""),".") -> . | S31: 283.15 | T31: =VLOOKUP(S31,D:F,3,FALSE) -> #N/A | V31: #3 | W31: =VLOOKUP(V31,B:F,5,FALSE()) -> Cesar Uriel Romo Trillo
A32: =IFERROR(__xludf.DUMMYFUNCTION("""COMPUTED_VALUE"""),"TRX1408") -> TRX1408 | B32: =IFERROR(__xludf.DUMMYFUNCTION("""COMPUTED_VALUE"""),"#4") -> #4 | C32: =IFERROR(__xludf.DUMMYFUNCTION("""COMPUTED_VALUE"""),46060.4173611111) -> 46060.417 | D32: =IFERROR(__xludf.DUMMYFUNCTION("""COMPUTED_VALUE"""),2196.88) -> 2196.88 | E32: =IFERROR(__xludf.DUMMYFUNCTION("""COMPUTED_VALUE"""),"USD") -> USD | F32: =IFERROR(__xludf.DUMMYFUNCTION("""COMPUTED_VALUE"""),"Daniel Autrique Echeveste") -> Daniel Autrique Echeveste | G32: =IFERROR(__xludf.DUMMYFUNCTION("""COMPUTED_VALUE"""),"20260203T00:00:00/COSMOPOL-FRONT DESK\3708 LAS VEGAS BLVD S\LAS VEGAS\89109 NV USA") -> 20260203T00:00:00/COSMOPOL-FRONT DESK\3708 LAS VEGAS BLVD S\LAS VEGAS\89109 NV USA | H32: =IFERROR(__xludf.DUMMYFUNCTION("""COMPUTED_VALUE"""),"T :00/Cosmopol Front Desk\3708 Las Vegas Blvd S\Las Vegas\ Nv USA") -> T :00/Cosmopol Front Desk\3708 Las Vegas Blvd S\Las Vegas\ Nv USA | I32: =IFERROR(__xludf.DUMMYFUNCTION("""COMPUTED_VALUE"""),"Sales") -> Sales | K32: =IFERROR(__xludf.DUMMYFUNCTION("""COMPUTED_VALUE"""),".") -> . | S32: 402.99 | T32: =VLOOKUP(S32,D:F,3,FALSE) -> #N/A | V32: #42 | W32: =VLOOKUP(V32,B:F,5,FALSE()) -> Rodrigo Perea
A33: =IFERROR(__xludf.DUMMYFUNCTION("""COMPUTED_VALUE"""),"TRX1758") -> TRX1758 | B33: =IFERROR(__xludf.DUMMYFUNCTION("""COMPUTED_VALUE"""),"#4") -> #4 | C33: =IFERROR(__xludf.DUMMYFUNCTION("""COMPUTED_VALUE"""),46061.4166666666) -> 46061.417 | D33: =IFERROR(__xludf.DUMMYFUNCTION("""COMPUTED_VALUE"""),100) -> 100 | E33: =IFERROR(__xludf.DUMMYFUNCTION("""COMPUTED_VALUE"""),"MXN") -> MXN | F33: =IFERROR(__xludf.DUMMYFUNCTION("""COMPUTED_VALUE"""),"Daniel Autrique Echeveste") -> Daniel Autrique Echeveste | G33: =IFERROR(__xludf.DUMMYFUNCTION("""COMPUTED_VALUE"""),"MEXPAGO*MUEVECIUDAD CIUDAD DE MEX MEX") -> MEXPAGO*MUEVECIUDAD CIUDAD DE MEX MEX | H33: =IFERROR(__xludf.DUMMYFUNCTION("""COMPUTED_VALUE"""),"Mexpago Mueveciudad Ciudad De Mex Mex") -> Mexpago Mueveciudad Ciudad De Mex Mex | I33: =IFERROR(__xludf.DUMMYFUNCTION("""COMPUTED_VALUE"""),"Sales") -> Sales | K33: =IFERROR(__xludf.DUMMYFUNCTION("""COMPUTED_VALUE"""),".") -> . | S33: 502.62 | T33: =VLOOKUP(S33,D:F,3,FALSE) -> #N/A | V33: #6 | W33: =VLOOKUP(V33,B:F,5,FALSE()) -> Fernando Sanchez Toledano
A34: =IFERROR(__xludf.DUMMYFUNCTION("""COMPUTED_VALUE"""),"TRX1501") -> TRX1501 | B34: =IFERROR(__xludf.DUMMYFUNCTION("""COMPUTED_VALUE"""),"#4") -> #4 | C34: =IFERROR(__xludf.DUMMYFUNCTION("""COMPUTED_VALUE"""),46064.4166666666) -> 46064.417 | D34: =IFERROR(__xludf.DUMMYFUNCTION("""COMPUTED_VALUE"""),870.55) -> 870.55 | E34: =IFERROR(__xludf.DUMMYFUNCTION("""COMPUTED_VALUE"""),"MXN") -> MXN | F34: =IFERROR(__xludf.DUMMYFUNCTION("""COMPUTED_VALUE"""),"Daniel Autrique Echeveste") -> Daniel Autrique Echeveste | G34: =IFERROR(__xludf.DUMMYFUNCTION("""COMPUTED_VALUE"""),"REST ENO VIRREYES CIUDAD DE MEX MEX") -> REST ENO VIRREYES CIUDAD DE MEX MEX | H34: =IFERROR(__xludf.DUMMYFUNCTION("""COMPUTED_VALUE"""),"Rest Eno Virreyes Ciudad De Mex Mex") -> Rest Eno Virreyes Ciudad De Mex Mex | K34: =IFERROR(__xludf.DUMMYFUNCTION("""COMPUTED_VALUE"""),".") -> . | S34: 246.26 | T34: =VLOOKUP(S34,D:F,3,FALSE) -> #N/A | V34: #20 | W34: =VLOOKUP(V34,B:F,5,FALSE()) -> #N/A
A35: =IFERROR(__xludf.DUMMYFUNCTION("""COMPUTED_VALUE"""),"TRX1629") -> TRX1629 | B35: =IFERROR(__xludf.DUMMYFUNCTION("""COMPUTED_VALUE"""),"#4") -> #4 | C35: =IFERROR(__xludf.DUMMYFUNCTION("""COMPUTED_VALUE"""),46067.4166666666) -> 46067.417 | D35: =IFERROR(__xludf.DUMMYFUNCTION("""COMPUTED_VALUE"""),5662.6) -> 5662.6 | E35: =IFERROR(__xludf.DUMMYFUNCTION("""COMPUTED_VALUE"""),"MXN") -> MXN | F35: =IFERROR(__xludf.DUMMYFUNCTION("""COMPUTED_VALUE"""),"Daniel Autrique Echeveste") -> Daniel Autrique Echeveste | G35: =IFERROR(__xludf.DUMMYFUNCTION("""COMPUTED_VALUE"""),"REST ZERU LOMAS CIUDAD DE MEX MEX") -> REST ZERU LOMAS CIUDAD DE MEX MEX | H35: =IFERROR(__xludf.DUMMYFUNCTION("""COMPUTED_VALUE"""),"Rest Zeru Lomas Ciudad De Mex Mex") -> Rest Zeru Lomas Ciudad De Mex Mex | K35: =IFERROR(__xludf.DUMMYFUNCTION("""COMPUTED_VALUE"""),".") -> . | S35: 251.27 | T35: =VLOOKUP(S35,D:F,3,FALSE) -> #N/A | V35: #58 | W35: =VLOOKUP(V35,B:F,5,FALSE()) -> Jose Rosas Ortiz
A36: =IFERROR(__xludf.DUMMYFUNCTION("""COMPUTED_VALUE"""),"TRX1043") -> TRX1043 | B36: =IFERROR(__xludf.DUMMYFUNCTION("""COMPUTED_VALUE"""),"#4") -> #4 | C36: =IFERROR(__xludf.DUMMYFUNCTION("""COMPUTED_VALUE"""),46071.4173611111) -> 46071.417 | D36: =IFERROR(__xludf.DUMMYFUNCTION("""COMPUTED_VALUE"""),1213.99) -> 1213.99 | E36: =IFERROR(__xludf.DUMMYFUNCTION("""COMPUTED_VALUE"""),"MXN") -> MXN | F36: =IFERROR(__xludf.DUMMYFUNCTION("""COMPUTED_VALUE"""),"Daniel Autrique Echeveste") -> Daniel Autrique Echeveste | G36: =IFERROR(__xludf.DUMMYFUNCTION("""COMPUTED_VALUE"""),"GASOL VALERO LOMALINDA CIUDAD DE MEX MEX") -> GASOL VALERO LOMALINDA CIUDAD DE MEX MEX | H36: =IFERROR(__xludf.DUMMYFUNCTION("""COMPUTED_VALUE"""),"Gasol Valero Lomalinda Ciudad De Mex Mex") -> Gasol Valero Lomalinda Ciudad De Mex Mex | K36: =IFERROR(__xludf.DUMMYFUNCTION("""COMPUTED_VALUE"""),".") -> . | S36: 6677 | T36: =VLOOKUP(S36,D:F,3,FALSE) -> #N/A | V36: #35 | W36: =VLOOKUP(V36,B:F,5,FALSE()) -> Termis
